<?xml version="1.0" encoding="utf-8"?>
<!-- This URDF was automatically created by SolidWorks to URDF Exporter! Originally created by Stephen Brawner (brawner@gmail.com) 
     Commit Version: 1.5.1-0-g916b5db  Build Version: 1.5.7152.31018
     For more information, please see http://wiki.ros.org/sw_urdf_exporter -->
<robot
  name="aragorn">

  <link name="base_footprint"/>
  <joint 
    name="base_footprint_to_base_link"
    type="fixed">
    <origin
      xyz="0 0 0.215"
      rpy="0 0 0" />
    <parent
      link="base_footprint" />
    <child
      link="base_link" />
    <axis
      xyz="0 0 1" />
  </joint> 

  <link
    name="base_link">
    <inertial>
      <origin
        xyz="-0.0403486248167869 -0.00918270719266345 0.316228196862835"
        rpy="0 0 0" />
      <mass
        value="219.993847036208" />
      <inertia
        ixx="41.6754828034538"
        ixy="-0.106413065258627"
        ixz="0.782685250341636"
        iyy="44.078983843434"
        iyz="-0.430942657277407"
        izz="7.63679261790245" />
    </inertial>
    <visual>
      <origin
        xyz="0 0 0"
        rpy="0 0 0" />
      <geometry>
        <mesh
          filename="package://aragorn_description/meshes/base_link.STL" />
      </geometry>
      <material
        name="">
        <color
          rgba="0.752941176470588 0.752941176470588 0.752941176470588 1" />
      </material>
    </visual>
    <collision>
      <origin
        xyz="0 0 0"
        rpy="0 0 0" />
      <geometry>
        <mesh
          filename="package://aragorn_description/meshes/base_link.STL" />
      </geometry>
    </collision>
  </link>
  <link
    name="left_swing_arm_link">
    <inertial>
      <origin
        xyz="0.0252820538711716 0.00177826971235748 -0.00249608151068294"
        rpy="0 0 0" />
      <mass
        value="2.34993446567487" />
      <inertia
        ixx="0.000656645614070494"
        ixy="0.000273388479641494"
        ixz="0.000674668619874366"
        iyy="0.0204702821567476"
        iyz="-4.55577159440825E-06"
        izz="0.0203400621395775" />
    </inertial>
    <visual>
      <origin
        xyz="0 0 0"
        rpy="0 0 0" />
      <geometry>
        <mesh
          filename="package://aragorn_description/meshes/left_swing_arm_link.STL" />
      </geometry>
      <material
        name="">
        <color
          rgba="0.752941176470588 0.752941176470588 0.752941176470588 1" />
      </material>
    </visual>
    <collision>
      <origin
        xyz="0 0 0"
        rpy="0 0 0" />
      <geometry>
        <mesh
          filename="package://aragorn_description/meshes/left_swing_arm_link.STL" />
      </geometry>
    </collision>
  </link>
  <joint
    name="left_swing_arm_joint"
    type="continuous">
    <origin
      xyz="0.136 0.1965 -0.14"
      rpy="0 0 0" />
    <parent
      link="base_link" />
    <child
      link="left_swing_arm_link" />
    <axis
      xyz="0 -1 0" />
  </joint>
  <link
    name="left_front_caster_arm_link">
    <inertial>
      <origin
        xyz="-0.0101764304807791 0.00103684809935464 -0.0266675630329053"
        rpy="0 0 0" />
      <mass
        value="0.0777788083339595" />
      <inertia
        ixx="3.52149915361053E-05"
        ixy="1.19534124059409E-06"
        ixz="-1.11237681502021E-05"
        iyy="3.25584920114246E-05"
        iyz="1.3170154061756E-06"
        izz="3.94012265015794E-05" />
    </inertial>
    <visual>
      <origin
        xyz="0 0 0"
        rpy="0 0 0" />
      <geometry>
        <mesh
          filename="package://aragorn_description/meshes/left_front_caster_arm_link.STL" />
      </geometry>
      <material
        name="">
        <color
          rgba="0.792156862745098 0.792156862745098 0.792156862745098 1" />
      </material>
    </visual>
    <collision>
      <origin
        xyz="0 0 0"
        rpy="0 0 0" />
      <geometry>
        <mesh
          filename="package://aragorn_description/meshes/left_front_caster_arm_link.STL" />
      </geometry>
    </collision>
  </link>
  <joint
    name="left_front_caster_arm_joint"
    type="continuous">
    <origin
      xyz="0.136999999999996 0 -0.0160000000000024"
      rpy="0 0 0" />
    <parent
      link="left_swing_arm_link" />
    <child
      link="left_front_caster_arm_link" />
    <axis
      xyz="0 0 1" />
    <limit
      effort="100000"
      velocity="1000" />
  </joint>
  <link
    name="left_front_caster_wheel_link">
    <inertial>
      <origin
        xyz="-8.17745908210377E-08 -3.33066907387547E-16 1.73472347597681E-17"
        rpy="0 0 0" />
      <mass
        value="0.426543248356679" />
      <inertia
        ixx="9.23799595784937E-05"
        ixy="3.11145489690233E-20"
        ixz="-3.25250886123016E-20"
        iyy="0.00012870095566462"
        iyz="-1.2548365939659E-10"
        izz="9.23855105540948E-05" />
    </inertial>
    <visual>
      <origin
        xyz="0 0 0"
        rpy="0 0 0" />
      <geometry>
        <mesh
          filename="package://aragorn_description/meshes/left_front_caster_wheel_link.STL" />
      </geometry>
      <material
        name="">
        <color
          rgba="0.792156862745098 0.792156862745098 0.792156862745098 1" />
      </material>
    </visual>
    <collision>
      <origin
        xyz="0 0 0"
        rpy="0 0 0" />
      <geometry>
        <mesh
          filename="package://aragorn_description/meshes/left_front_caster_wheel_link.STL" />
      </geometry>
    </collision>
  </link>
  <joint
    name="left_front_caster_wheel_joint"
    type="continuous">
    <origin
      xyz="-0.0249999999999989 0 -0.0429999999999974"
      rpy="0 0 0" />
    <parent
      link="left_front_caster_arm_link" />
    <child
      link="left_front_caster_wheel_link" />
    <axis
      xyz="0 -1 0" />
  </joint>
  <link
    name="left_wheel_link">
    <inertial>
      <origin
        xyz="-1.73472347597681E-18 -0.000962802918484051 0"
        rpy="0 0 0" />
      <mass
        value="9.55808535243556" />
      <inertia
        ixx="0.0172238206025619"
        ixy="-3.98159536913938E-19"
        ixz="-1.35063020093918E-18"
        iyy="0.0285095245192058"
        iyz="3.33100181770154E-20"
        izz="0.0172238206025619" />
    </inertial>
    <visual>
      <origin
        xyz="0 0 0"
        rpy="0 0 0" />
      <geometry>
        <mesh
          filename="package://aragorn_description/meshes/left_wheel_link.STL" />
      </geometry>
      <material
        name="">
        <color
          rgba="0.792156862745098 0.792156862745098 0.792156862745098 1" />
      </material>
    </visual>
    <collision>
      <origin
        xyz="0 0 0"
        rpy="0 0 0" />
      <geometry>
        <mesh
          filename="package://aragorn_description/meshes/left_wheel_link.STL" />
      </geometry>
    </collision>
  </link>
  <joint
    name="left_wheel_joint"
    type="continuous">
    <origin
      xyz="-0.137500000000002 0.0596000000000001 0"
      rpy="0 0 0" />
    <parent
      link="left_swing_arm_link" />
    <child
      link="left_wheel_link" />
    <axis
      xyz="0 1 0" />
  </joint>
  <link
    name="left_rear_caster_arm_link">
    <inertial>
      <origin
        xyz="-0.0101764304807791 0.00103684809935445 -0.0266675630329053"
        rpy="0 0 0" />
      <mass
        value="0.0777788083339599" />
      <inertia
        ixx="3.52149915361054E-05"
        ixy="1.19534124059411E-06"
        ixz="-1.11237681502021E-05"
        iyy="3.25584920114245E-05"
        iyz="1.31701540617563E-06"
        izz="3.94012265015795E-05" />
    </inertial>
    <visual>
      <origin
        xyz="0 0 0"
        rpy="0 0 0" />
      <geometry>
        <mesh
          filename="package://aragorn_description/meshes/left_rear_caster_arm_link.STL" />
      </geometry>
      <material
        name="">
        <color
          rgba="0.792156862745098 0.792156862745098 0.792156862745098 1" />
      </material>
    </visual>
    <collision>
      <origin
        xyz="0 0 0"
        rpy="0 0 0" />
      <geometry>
        <mesh
          filename="package://aragorn_description/meshes/left_rear_caster_arm_link.STL" />
      </geometry>
    </collision>
  </link>
  <joint
    name="left_rear_caster_arm_joint"
    type="continuous">
    <origin
      xyz="-0.276 0.1965 -0.156"
      rpy="0 0 0" />
    <parent
      link="base_link" />
    <child
      link="left_rear_caster_arm_link" />
    <axis
      xyz="0 0 1" />
    <limit
      effort="100000"
      velocity="1000" />
  </joint>
  <link
    name="left_rear_caster_wheel_link">
    <inertial>
      <origin
        xyz="8.17745907655265E-08 1.11022302462516E-16 1.04083408558608E-17"
        rpy="0 0 0" />
      <mass
        value="0.426543248356681" />
      <inertia
        ixx="9.237995957848E-05"
        ixy="1.98228295150495E-20"
        ixz="2.46982996889143E-20"
        iyy="0.000128700955664593"
        iyz="1.25483659469682E-10"
        izz="9.23855105540812E-05" />
    </inertial>
    <visual>
      <origin
        xyz="0 0 0"
        rpy="0 0 0" />
      <geometry>
        <mesh
          filename="package://aragorn_description/meshes/left_rear_caster_wheel_link.STL" />
      </geometry>
      <material
        name="">
        <color
          rgba="0.792156862745098 0.792156862745098 0.792156862745098 1" />
      </material>
    </visual>
    <collision>
      <origin
        xyz="0 0 0"
        rpy="0 0 0" />
      <geometry>
        <mesh
          filename="package://aragorn_description/meshes/left_rear_caster_wheel_link.STL" />
      </geometry>
    </collision>
  </link>
  <joint
    name="left_rear_caster_wheel_joint"
    type="continuous">
    <origin
      xyz="-0.025 0 -0.043"
      rpy="0 0 0" />
    <parent
      link="left_rear_caster_arm_link" />
    <child
      link="left_rear_caster_wheel_link" />
    <axis
      xyz="0 1 0" />
  </joint>
  <link
    name="right_swing_arm_link">
    <inertial>
      <origin
        xyz="0.0252577773571477 0.00250575410925884 -0.0332771351931779"
        rpy="0 0 0" />
      <mass
        value="2.3521930746689" />
      <inertia
        ixx="0.00065716338841482"
        ixy="-0.000674093946357969"
        ixz="-0.000273445794447136"
        iyy="0.0203417544787147"
        iyz="-4.58971740988904E-06"
        izz="0.020472002126438" />
    </inertial>
    <visual>
      <origin
        xyz="0 0 0"
        rpy="0 0 0" />
      <geometry>
        <mesh
          filename="package://aragorn_description/meshes/right_swing_arm_link.STL" />
      </geometry>
      <material
        name="">
        <color
          rgba="0.752941176470588 0.752941176470588 0.752941176470588 1" />
      </material>
    </visual>
    <collision>
      <origin
        xyz="0 0 0"
        rpy="0 0 0" />
      <geometry>
        <mesh
          filename="package://aragorn_description/meshes/right_swing_arm_link.STL" />
      </geometry>
    </collision>
  </link>
  <joint
    name="right_swing_arm_joint"
    type="continuous">
    <origin
      xyz="0.135999999999999 -0.164999999999855 -0.14"
      rpy="-1.5707963267949 0 0" />
    <parent
      link="base_link" />
    <child
      link="right_swing_arm_link" />
    <axis
      xyz="0 0 1" />
  </joint>
  <link
    name="right_front_caster_arm_link">
    <inertial>
      <origin
        xyz="-0.0101764304807792 0.00103684809935475 -0.0266675630329053"
        rpy="0 0 0" />
      <mass
        value="0.0777788083339588" />
      <inertia
        ixx="3.52149915361052E-05"
        ixy="1.19534124059405E-06"
        ixz="-1.11237681502021E-05"
        iyy="3.25584920114245E-05"
        iyz="1.31701540617562E-06"
        izz="3.94012265015793E-05" />
    </inertial>
    <visual>
      <origin
        xyz="0 0 0"
        rpy="0 0 0" />
      <geometry>
        <mesh
          filename="package://aragorn_description/meshes/right_front_caster_arm_link.STL" />
      </geometry>
      <material
        name="">
        <color
          rgba="0.792156862745098 0.792156862745098 0.792156862745098 1" />
      </material>
    </visual>
    <collision>
      <origin
        xyz="0 0 0"
        rpy="0 0 0" />
      <geometry>
        <mesh
          filename="package://aragorn_description/meshes/right_front_caster_arm_link.STL" />
      </geometry>
    </collision>
  </link>
  <joint
    name="right_front_caster_arm_joint"
    type="continuous">
    <origin
      xyz="0.137000000000001 0.016 -0.0315000000001454"
      rpy="1.5707963267949 0 0" />
    <parent
      link="right_swing_arm_link" />
    <child
      link="right_front_caster_arm_link" />
    <axis
      xyz="0 0 1" />
    <limit
      effort="100000"
      velocity="1000" />
  </joint>
  <link
    name="right_front_caster_wheel_link">
    <inertial>
      <origin
        xyz="-8.17745907932821E-08 -3.05311331771918E-16 3.46944695195361E-18"
        rpy="0 0 0" />
      <mass
        value="0.42654324835668" />
      <inertia
        ixx="9.2379959578494E-05"
        ixy="2.1637551675201E-20"
        ixz="-2.56171294338236E-20"
        iyy="0.000128700955664621"
        iyz="-1.25483659404144E-10"
        izz="9.23855105540952E-05" />
    </inertial>
    <visual>
      <origin
        xyz="0 0 0"
        rpy="0 0 0" />
      <geometry>
        <mesh
          filename="package://aragorn_description/meshes/right_front_caster_wheel_link.STL" />
      </geometry>
      <material
        name="">
        <color
          rgba="0.792156862745098 0.792156862745098 0.792156862745098 1" />
      </material>
    </visual>
    <collision>
      <origin
        xyz="0 0 0"
        rpy="0 0 0" />
      <geometry>
        <mesh
          filename="package://aragorn_description/meshes/right_front_caster_wheel_link.STL" />
      </geometry>
    </collision>
  </link>
  <joint
    name="right_front_caster_wheel_joint"
    type="continuous">
    <origin
      xyz="-0.0250000000000017 0 -0.0429999999999972"
      rpy="0 0 0" />
    <parent
      link="right_front_caster_arm_link" />
    <child
      link="right_front_caster_wheel_link" />
    <axis
      xyz="0 -1 0" />
  </joint>
  <link
    name="right_wheel_link">
    <inertial>
      <origin
        xyz="-2.38524477946811E-18 0.00096280291848394 -1.38777878078145E-17"
        rpy="0 0 0" />
      <mass
        value="9.55808535243556" />
      <inertia
        ixx="0.0172238206025619"
        ixy="1.58327136905796E-19"
        ixz="3.39376522032136E-19"
        iyy="0.0285095245192058"
        iyz="1.46985395920989E-19"
        izz="0.0172238206025619" />
    </inertial>
    <visual>
      <origin
        xyz="0 0 0"
        rpy="0 0 0" />
      <geometry>
        <mesh
          filename="package://aragorn_description/meshes/right_wheel_link.STL" />
      </geometry>
      <material
        name="">
        <color
          rgba="0.792156862745098 0.792156862745098 0.792156862745098 1" />
      </material>
    </visual>
    <collision>
      <origin
        xyz="0 0 0"
        rpy="0 0 0" />
      <geometry>
        <mesh
          filename="package://aragorn_description/meshes/right_wheel_link.STL" />
      </geometry>
    </collision>
  </link>
  <joint
    name="right_wheel_joint"
    type="continuous">
    <origin
      xyz="-0.1375 0 -0.0911000000001454"
      rpy="1.5707963267949 0 0" />
    <parent
      link="right_swing_arm_link" />
    <child
      link="right_wheel_link" />
    <axis
      xyz="0 1 0" />
  </joint>
  <link
    name="right_rear_caster_arm_link">
    <inertial>
      <origin
        xyz="-0.0101764304807792 0.00103684809935448 -0.0266675630329053"
        rpy="0 0 0" />
      <mass
        value="0.0777788083339599" />
      <inertia
        ixx="3.52149915361053E-05"
        ixy="1.19534124059416E-06"
        ixz="-1.11237681502021E-05"
        iyy="3.25584920114245E-05"
        iyz="1.31701540617562E-06"
        izz="3.94012265015795E-05" />
    </inertial>
    <visual>
      <origin
        xyz="0 0 0"
        rpy="0 0 0" />
      <geometry>
        <mesh
          filename="package://aragorn_description/meshes/right_rear_caster_arm_link.STL" />
      </geometry>
      <material
        name="red">
        <color
          rgba="0.792156862745098 0.792156862745098 0.792156862745098 1" />
      </material>
    </visual>
    <collision>
      <origin
        xyz="0 0 0"
        rpy="0 0 0" />
      <geometry>
        <mesh
          filename="package://aragorn_description/meshes/right_rear_caster_arm_link.STL" />
      </geometry>
    </collision>
  </link>
  <joint
    name="right_rear_caster_arm_joint"
    type="continuous">
    <origin
      xyz="-0.276 -0.1965 -0.156"
      rpy="0 0 0" />
    <parent
      link="base_link" />
    <child
      link="right_rear_caster_arm_link" />
    <axis
      xyz="0 0 1" />
    <limit
      effort="100000"
      velocity="1000" />
  </joint>
  <link
    name="right_rear_caster_wheel_link">
    <inertial>
      <origin
        xyz="-8.17745907655265E-08 -4.44089209850063E-16 -2.42861286636753E-17"
        rpy="0 0 0" />
      <mass
        value="0.426543248356681" />
      <inertia
        ixx="9.23799595784982E-05"
        ixy="-5.10774118716882E-21"
        ixz="-2.95035227706681E-20"
        iyy="0.000128700955664626"
        iyz="-1.2548365982896E-10"
        izz="9.23855105540994E-05" />
    </inertial>
    <visual>
      <origin
        xyz="0 0 0"
        rpy="0 0 0" />
      <geometry>
        <mesh
          filename="package://aragorn_description/meshes/right_rear_caster_wheel_link.STL" />
      </geometry>
      <material
        name="">
        <color
          rgba="0.792156862745098 0.792156862745098 0.792156862745098 1" />
      </material>
    </visual>
    <collision>
      <origin
        xyz="0 0 0"
        rpy="0 0 0" />
      <geometry>
        <mesh
          filename="package://aragorn_description/meshes/right_rear_caster_wheel_link.STL" />
      </geometry>
    </collision>
  </link>
  <joint
    name="right_rear_caster_wheel_joint"
    type="continuous">
    <origin
      xyz="-0.0250000000000017 0 -0.0430000000000034"
      rpy="0 0 0" />
    <parent
      link="right_rear_caster_arm_link" />
    <child
      link="right_rear_caster_wheel_link" />
    <axis
      xyz="0 -1 0" />
  </joint>
  <link
    name="front_lidar_mount_point_link">
    <inertial>
      <origin
        xyz="-0.000494072444837901 -0.000402434458443346 0.0194819853221781"
        rpy="0 0 0" />
      <mass
        value="1.31125166858489" />
      <inertia
        ixx="0.000628704433687881"
        ixy="8.290475363551E-06"
        ixz="7.43194940276994E-06"
        iyy="0.000625289700870527"
        iyz="6.05314182595885E-06"
        izz="0.000886050760133868" />
    </inertial>
    <visual>
      <origin
        xyz="0 0 0"
        rpy="0 0 0" />
      <geometry>
        <mesh
          filename="package://aragorn_description/meshes/front_lidar_mount_point_link.STL" />
      </geometry>
      <material
        name="">
        <color
          rgba="0.792156862745098 0.792156862745098 0.792156862745098 1" />
      </material>
    </visual>
    <collision>
      <origin
        xyz="0 0 0"
        rpy="0 0 0" />
      <geometry>
        <mesh
          filename="package://aragorn_description/meshes/front_lidar_mount_point_link.STL" />
      </geometry>
    </collision>
  </link>
  <joint
    name="front_lidar_mount_point_joint"
    type="fixed">
    <origin
      xyz="0.3 0 -0.0198"
      rpy="0 0 0" />
    <parent
      link="base_link" />
    <child
      link="front_lidar_mount_point_link" />
    <axis
      xyz="0 0 0" />
  </joint>
  <link
    name="front_depth_cam_link">
    <inertial>
      <origin
        xyz="-0.014017564484296 0.00275959923000608 2.06545004441949E-05"
        rpy="0 0 0" />
      <mass
        value="0.267031423454358" />
      <inertia
        ixx="0.000177634634455598"
        ixy="-6.78475808866593E-07"
        ixz="6.58752370419804E-08"
        iyy="2.66461581525618E-05"
        iyz="1.03679909676601E-07"
        izz="0.000177829735950425" />
    </inertial>
    <visual>
      <origin
        xyz="0 0 0"
        rpy="0 0 0" />
      <geometry>
        <mesh
          filename="package://aragorn_description/meshes/front_depth_cam_link.STL" />
      </geometry>
      <material
        name="">
        <color
          rgba="0.792156862745098 0.792156862745098 0.792156862745098 1" />
      </material>
    </visual>
    <collision>
      <origin
        xyz="0 0 0"
        rpy="0 0 0" />
      <geometry>
        <mesh
          filename="package://aragorn_description/meshes/front_depth_cam_link.STL" />
      </geometry>
    </collision>
  </link>
  <joint
    name="front_depth_cam_joint"
    type="fixed">
    <origin
      xyz="0.393881187506735 0 0.0739999999999997"
      rpy="0 0 0" />
    <parent
      link="base_link" />
    <child
      link="front_depth_cam_link" />
    <axis
      xyz="0 0 0" />
  </joint>
  <link
    name="rear_depth_cam_link">
    <inertial>
      <origin
        xyz="-0.0140175644843305 0.00275959922988988 2.06545004438619E-05"
        rpy="0 0 0" />
      <mass
        value="0.267031423453322" />
      <inertia
        ixx="0.000177634634454661"
        ixy="-6.78475808589883E-07"
        ixz="6.5875237043186E-08"
        iyy="2.66461581524812E-05"
        iyz="1.03679909676012E-07"
        izz="0.000177829735949408" />
    </inertial>
    <visual>
      <origin
        xyz="0 0 0"
        rpy="0 0 0" />
      <geometry>
        <mesh
          filename="package://aragorn_description/meshes/rear_depth_cam_link.STL" />
      </geometry>
      <material
        name="">
        <color
          rgba="0.792156862745098 0.792156862745098 0.792156862745098 1" />
      </material>
    </visual>
    <collision>
      <origin
        xyz="0 0 0"
        rpy="0 0 0" />
      <geometry>
        <mesh
          filename="package://aragorn_description/meshes/rear_depth_cam_link.STL" />
      </geometry>
    </collision>
  </link>
  <joint
    name="rear_depth_cam_joint"
    type="fixed">
    <origin
      xyz="-0.37 0 0.074"
      rpy="0 0 -3.14159265358979" />
    <parent
      link="base_link" />
    <child
      link="rear_depth_cam_link" />
    <axis
      xyz="0 0 0" />
  </joint>

  <gazebo reference="right_wheel_link">
    <mu1>1.0</mu1>
    <mu2>1.0</mu2>
    <kp>1000000.0</kp> 
    <kd>100.0</kd>
    <minDepth>0.001</minDepth>
    <maxVel>1.0</maxVel>
    <selfCollide>true</selfCollide>
    <material>Gazebo/Grey</material>
  </gazebo>
  <gazebo reference="left_wheel_link">
    <mu1>1.0</mu1>
    <mu2>1.0</mu2>
    <kp>1000000.0</kp> 
    <kd>100.0</kd>
    <minDepth>0.001</minDepth>
    <maxVel>1.0</maxVel>
    <selfCollide>true</selfCollide>
    <material>Gazebo/Grey</material>
  </gazebo>
  <gazebo reference="left_rear_caster_wheel_link">
    <mu1>0.5</mu1>
    <mu2>0.5</mu2>
    <kp>1000000.0</kp> 
    <kd>100.0</kd>
    <minDepth>0.001</minDepth>
    <maxVel>1.0</maxVel>
    <selfCollide>true</selfCollide>
    <material>Gazebo/Grey</material>
  </gazebo>
  <gazebo reference="left_front_caster_wheel_link">
    <mu1>0.5</mu1>
    <mu2>0.5</mu2>
    <kp>1000000.0</kp> 
    <kd>100.0</kd>
    <minDepth>0.001</minDepth>
    <maxVel>1.0</maxVel>
    <selfCollide>true</selfCollide>
    <material>Gazebo/Grey</material>
  </gazebo>
  <gazebo reference="right_rear_caster_wheel_link">
    <mu1>0.5</mu1>
    <mu2>0.5</mu2>
    <kp>1000000.0</kp> 
    <kd>100.0</kd>
    <minDepth>0.001</minDepth>
    <maxVel>1.0</maxVel>
    <selfCollide>true</selfCollide>
    <material>Gazebo/Grey</material>
  </gazebo>
  <gazebo reference="right_front_caster_wheel_link">
    <mu1>0.5</mu1>
    <mu2>0.5S</mu2>
    <kp>1000000.0</kp> 
    <kd>100.0</kd>
    <minDepth>0.001</minDepth>
    <maxVel>1.0</maxVel>
    <selfCollide>true</selfCollide>
    <material>Gazebo/Grey</material>
  </gazebo>

  <!-- Add the differential_drive_controller -->
  <!--<gazebo>
    <plugin name="differential_drive_controller" filename="libgazebo_ros_diff_drive.so">
        <rosDebugLevel>Debug</rosDebugLevel>
        <legacyMode>false</legacyMode>
        <publishWheelTF>true</publishWheelTF>
        <publishTf>50</publishTf>
        <publishOdom>50</publishOdom>
        <publishWheelJointState>true</publishWheelJointState>
        <alwaysOn>true</alwaysOn>
        <leftJoint>left_wheel_joint</leftJoint>
        <rightJoint>right_wheel_joint</rightJoint>
        <wheelSeparation>0.393</wheelSeparation>
        <wheelDiameter>0.17</wheelDiameter>
        <wheelTorque>100</wheelTorque>
        <wheelAcceleration>1.8</wheelAcceleration>
        <commandTopic>/cmd_vel</commandTopic>
        <odometryTopic>/odom</odometryTopic>
        <odometryFrame>/odom</odometryFrame>
        <publishOdomTF>true</publishOdomTF>
        <odometrySource>world</odometrySource>
        <publishOdom>true</publishOdom>
        <robotBaseFrame>base_footprint</robotBaseFrame>
        <updateRate>50.0</updateRate>
    </plugin>
  </gazebo>-->

 <gazebo>
    <plugin name="differential_drive_controller" filename="libgazebo_ros_diff_drive.so">
        <updateRate>50.0</updateRate>
        <leftJoint>left_wheel_joint</leftJoint>
        <rightJoint>right_wheel_joint</rightJoint>
        <wheelSeparation>0.393</wheelSeparation>
        <wheelDiameter>0.17</wheelDiameter>
        <wheelAcceleration>1.8</wheelAcceleration>
        <wheelTorque>100</wheelTorque>
        <commandTopic>cmd_vel_filter</commandTopic>
        <odometryTopic>odom</odometryTopic>
        <odometryFrame>odom</odometryFrame>
        <robotBaseFrame>base_footprint</robotBaseFrame>
        <odometrySource>1</odometrySource>
        <publishWheelTF>true</publishWheelTF>
        <publishOdom>true</publishOdom>
        <publishWheelJointState>true</publishWheelJointState>
        <legacyMode>false</legacyMode>
    </plugin>
  </gazebo>







  <gazebo>
    <plugin filename="libgazebo_ros_joint_state_publisher.so" name="joint_state_publisher">
      <jointName>right_wheel_joint, left_wheel_joint</jointName>
      <updateRate>10.0</updateRate>
      <alwaysOn>true</alwaysOn>
    </plugin>
  </gazebo>

  <link name="laser" />

  <joint name="lidar_mount_to_laser" type="fixed">
    <parent link="front_lidar_mount_point_link"/>
    <child link="laser"/>
    <origin rpy="0 0 0" xyz="0 0 0.0325"/>
  </joint>

  <!-- Add hokuyo -->
  <gazebo reference="laser">
    <sensor type="gpu_ray" name="head_hokuyo_sensor">
      <pose>0 0 0 0 0 0</pose>
      <visualize>false</visualize>
      <update_rate>40</update_rate>
      <ray>
        <scan>
          <horizontal>
            <samples>720</samples>
            <resolution>1</resolution>
            <!-- 120 degrees -->
            <min_angle>-2.0944</min_angle>
            <max_angle>2.0944</max_angle>
          </horizontal>
        </scan>
        <range>
          <min>0.05</min>
          <max>20</max>
          <resolution>0.01</resolution>
        </range>
        <noise>
          <type>gaussian</type>
          <!-- Noise parameters based on published spec for Hokuyo laser
               achieving "+-30mm" accuracy at range < 10m.  A mean of 0.0m and
               stddev of 0.01m will put 99.7% of samples within 0.03m of the true
               reading. -->
          <mean>0.0</mean>
          <stddev>0.01</stddev>
        </noise>
      </ray>
      <plugin name="gazebo_ros_base_hokuyo_controller" filename="libgazebo_ros_gpu_laser.so">
        <gaussianNoise>0.005</gaussianNoise>
        <topicName>scan</topicName>
        <frameName>laser</frameName>
      </plugin>
    </sensor>
  </gazebo>  

  <!-- Add Front Kinect -->
  <link name="front_kinect_link">
    <inertial>
      <mass value="0.001"/>
      <origin xyz="0 0 0"/>
      <inertia ixx="0.000001" ixy="0.0" ixz="0.0" iyy="0.000001" iyz="0.0" izz="0.000001"/>
    </inertial>
  </link>

  <joint name="front_kinect_joint" type="fixed">
    <parent link="front_depth_cam_link"/>
    <child link="front_kinect_link"/>
    <origin xyz="0.0 0.0 0.0" rpy="0.0 0.0 0.0"/>
  </joint>

  <link name="front_kinect_view_link">
    <inertial>
      <mass value="0.001"/>
      <origin xyz="0 0 0"/>
      <inertia ixx="0.000001" ixy="0.0" ixz="0.0" iyy="0.000001" iyz="0.0" izz="0.000001"/>
    </inertial>
  </link>

  <joint name="front_kinect_view_joint" type="fixed">
    <parent link="front_kinect_link"/>
    <child link="front_kinect_view_link"/>
    <origin xyz="0.0 0.0 0.0" rpy="-1.5708 0.0 -1.5708"/>
  </joint>

  <gazebo reference="front_kinect_link">
    <sensor type="depth" name="front_depth_camera">
      <pose>0 0 0 0 0 0</pose>
      <visualize>true</visualize>
      <update_rate>30.0</update_rate>
      <camera name="front_camera">
        <horizontal_fov>1.3962634</horizontal_fov>
        <image>
          <width>800</width>
          <height>800</height>
          <format>R8G8B8</format>
        </image>
        <clip>
          <near>0.02</near>
          <far>300</far>
        </clip>
        <noise>
          <type>gaussian</type>
          <!-- Noise is sampled independently per pixel on each frame.
               That pixel's noise value is added to each of its color
               channels, which at that point lie in the range [0,1]. -->
          <mean>0.0</mean>
          <stddev>0.007</stddev>
        </noise>
      </camera>
      <plugin name="front_kinect_controller" filename="libgazebo_ros_openni_kinect.so">
        <baseline>0.2</baseline>
        <alwaysOn>true</alwaysOn>
        <updateRate>1.0</updateRate>
        <cameraName>front_depthcam_ir</cameraName>
        <imageTopicName>/front_depthcam/depth/image_raw</imageTopicName>
        <cameraInfoTopicName>/front_depthcam/depth/camera_info</cameraInfoTopicName>
        <depthImageTopicName>/front_depthcam/depth/image_raw</depthImageTopicName>
        <depthImageInfoTopicName>/front_depthcam/depth/camera_info</depthImageInfoTopicName>
        <depthImageCameraInfoTopicName>front_image_raw</depthImageCameraInfoTopicName>
        <pointCloudTopicName>/front_depthcam/depth/points</pointCloudTopicName>
        <frameName>front_kinect_view_link</frameName>
        <pointCloudCutoff>0.5</pointCloudCutoff>
        <distortionK1>0.0</distortionK1>
        <distortionK2>0.0</distortionK2>
        <distortionK3>0.0</distortionK3>
        <distortionT1>0.0</distortionT1>
        <distortionT2>0.0</distortionT2>
        <CxPrime>0</CxPrime>
        <Cx>0</Cx>
        <Cy>0</Cy>
        <focalLength>0</focalLength>
        <hackBaseline>0</hackBaseline>
      </plugin>
    </sensor>
  </gazebo>



 <joint name="imu_joint" type="fixed">
    <parent link="base_link"/>
    <child link="imu_link"/>
    <origin xyz="0.032 0 0.068" rpy="0 0 0"/>
  </joint>

  <link name="imu_link"/>

  <gazebo reference="imu_link">
    <sensor type="imu" name="imu">
      <always_on>true</always_on>
      <visualize>false</visualize>
    </sensor>
    <material>Gazebo/FlatBlack</material>
  </gazebo>

  <gazebo>
    <plugin name="imu_plugin" filename="libgazebo_ros_imu.so">
      <alwaysOn>true</alwaysOn>
      <bodyName>imu_link</bodyName>
      <frameName>imu_link</frameName>
      <topicName>imu</topicName>
      <serviceName>imu_service</serviceName>
      <gaussianNoise>0.0</gaussianNoise>
      <updateRate>200</updateRate>
      <imu>
        <noise>
          <type>gaussian</type>
          <rate>
            <mean>0.0</mean>
            <stddev>2e-4</stddev>
            <bias_mean>0.0000075</bias_mean>
            <bias_stddev>0.0000008</bias_stddev>
          </rate>
          <accel>
            <mean>0.0</mean>
            <stddev>1.7e-2</stddev>
            <bias_mean>0.1</bias_mean>
            <bias_stddev>0.001</bias_stddev>
          </accel>
        </noise>
      </imu>
    </plugin>
  </gazebo>



 <!--  Add ultrasonuc   Middle Left Fornt  -->

  <joint name="ir_middle_left_front_joint" type="fixed">
    <parent link="base_link"/>
    <child link="ir_middle_left_front_link"/>
    <origin xyz="0.35 -0.06 -0.13" rpy="0 0 0"/>
  </joint>

  <link name="ir_middle_left_front_link"/>

  <gazebo reference="ir_middle_left_front_link">        
   <sensor type="ray" name="ir_middle_left_front">
      <pose>0 0 0 0 0 0</pose>
      <visualize>false</visualize>
      <update_rate>50</update_rate>
      <ray>
         <scan>
            <horizontal>
               <samples>10</samples>
               <resolution>1</resolution> 
               <min_angle>-0.0349066</min_angle>
               <max_angle>0.0349066</max_angle>
            </horizontal>
            <vertical>
               <samples>10</samples>
               <resolution>1</resolution> 
               <min_angle>-0.0174533</min_angle>
               <max_angle>0.0174533</max_angle> 
            </vertical>
         </scan>
         <range>
            <min>0.01</min>
            <max>2</max>
            <resolution>0.02</resolution>
         </range>
      </ray>
      <plugin filename="libgazebo_ros_range.so" name="gazebo_ros_range">
         <gaussianNoise>0.005</gaussianNoise>
         <alwaysOn>true</alwaysOn>
         <updateRate>50</updateRate>
         <topicName>sensor/ir_middle_left_front</topicName>
         <frameName>ir_middle_left_front_link</frameName>
         <radiation>INFRARED</radiation>
         <fov>0.2967</fov>
      </plugin>
   </sensor>  
   </gazebo>

   <!--  Add ultrasonuc   Middle Right Fornt  -->

  <joint name="ir_middle_right_front_joint" type="fixed">
    <parent link="base_link"/>
    <child link="ir_middle_right_front_link"/>
    <origin xyz="0.35 0.06 -0.13" rpy="0 0 0"/>
  </joint>

  <link name="ir_middle_right_front_link"/>

  <gazebo reference="ir_middle_right_front_link">        
   <sensor type="ray" name="ir_middle_right_front">
      <pose>0 0 0 0 0 0</pose>
      <visualize>false</visualize>
      <update_rate>50</update_rate>
      <ray>
         <scan>
            <horizontal>
               <samples>10</samples>
               <resolution>1</resolution> 
               <min_angle>-0.0349066</min_angle>
               <max_angle>0.0349066</max_angle>
            </horizontal>
            <vertical>
               <samples>10</samples>
               <resolution>1</resolution> 
               <min_angle>-0.0174533</min_angle>
               <max_angle>0.0174533</max_angle> 
            </vertical>
         </scan>
         <range>
            <min>0.01</min>
            <max>2</max>
            <resolution>0.02</resolution>
         </range>
      </ray>
      <plugin filename="libgazebo_ros_range.so" name="gazebo_ros_range">
         <gaussianNoise>0.005</gaussianNoise>
         <alwaysOn>true</alwaysOn>
         <updateRate>50</updateRate>
         <topicName>sensor/ir_middle_right_front</topicName>
         <frameName>ir_middle_right_front_link</frameName>
         <radiation>INFRARED</radiation>
         <fov>0.2967</fov>
      </plugin>
   </sensor>  
   </gazebo>
  

  <!--  Add ultrasonuc   Left Fornt  -->

  <joint name="ir_left_front_joint" type="fixed">
    <parent link="base_link"/>
    <child link="ir_left_front_link"/>
    <origin xyz="0.35 0.18 -0.13" rpy="0 0 0"/>
  </joint>

  <link name="ir_left_front_link"/>

  <gazebo reference="ir_left_front_link">        
   <sensor type="ray" name="ir_left_front">
      <pose>0 0 0 0 0 0</pose>
      <visualize>false</visualize>
      <update_rate>50</update_rate>
      <ray>
         <scan>
            <horizontal>
               <samples>10</samples>
               <resolution>1</resolution> 
               <min_angle>-0.0349066</min_angle>
               <max_angle>0.0349066</max_angle>
            </horizontal>
            <vertical>
               <samples>10</samples>
               <resolution>1</resolution> 
               <min_angle>-0.0174533</min_angle>
               <max_angle>0.0174533</max_angle> 
            </vertical>
         </scan>
         <range>
            <min>0.01</min>
            <max>2</max>
            <resolution>0.02</resolution>
         </range>
      </ray>
      <plugin filename="libgazebo_ros_range.so" name="gazebo_ros_range">
         <gaussianNoise>0.005</gaussianNoise>
         <alwaysOn>true</alwaysOn>
         <updateRate>50</updateRate>
         <topicName>sensor/ir_left_front</topicName>
         <frameName>ir_left_front_link</frameName>
         <radiation>INFRARED</radiation>
         <fov>0.2967</fov>
      </plugin>
   </sensor>  
   </gazebo>



     <!--  Add ultrasonuc   Right Fornt  -->

  <joint name="ir_right_front_joint" type="fixed">
    <parent link="base_link"/>
    <child link="ir_right_front_link"/>
    <origin xyz="0.35 -0.18 -0.13" rpy="0 0 0"/>
  </joint>

  <link name="ir_right_front_link"/>

  <gazebo reference="ir_right_front_link">        
   <sensor type="ray" name="ir_right_front">
      <pose>0 0 0 0 0 0</pose>
      <visualize>false</visualize>
      <update_rate>50</update_rate>
      <ray>
         <scan>
            <horizontal>
               <samples>10</samples>
               <resolution>1</resolution> 
               <min_angle>-0.0349066</min_angle>
               <max_angle>0.0349066</max_angle>
            </horizontal>
            <vertical>
               <samples>10</samples>
               <resolution>1</resolution> 
               <min_angle>-0.0174533</min_angle>
               <max_angle>0.0174533</max_angle> 
            </vertical>
         </scan>
         <range>
            <min>0.01</min>
            <max>2</max>
            <resolution>0.02</resolution>
         </range>
      </ray>
      <plugin filename="libgazebo_ros_range.so" name="gazebo_ros_range">
         <gaussianNoise>0.005</gaussianNoise>
         <alwaysOn>true</alwaysOn>
         <updateRate>50</updateRate>
         <topicName>sensor/ir_right_front</topicName>
         <frameName>ir_right_front_link</frameName>
         <radiation>INFRARED</radiation>
         <fov>0.2967</fov>
      </plugin>
   </sensor>  
   </gazebo>


<!--  Add ultrasonuc   Right   -->

  <joint name="ir_right_joint" type="fixed">
    <parent link="base_link"/>
    <child link="ir_right_link"/>
    <origin xyz="0.21 -0.25 -0.13" rpy="0 0 -1.57"/>
  </joint>

  <link name="ir_right_link"/>

  <gazebo reference="ir_right_link">        
   <sensor type="ray" name="ir_right">
      <pose>0 0 0 0 0 0</pose>
      <visualize>false</visualize>
      <update_rate>50</update_rate>
      <ray>
         <scan>
            <horizontal>
               <samples>10</samples>
               <resolution>1</resolution> 
               <min_angle>-0.0349066</min_angle>
               <max_angle>0.0349066</max_angle>
            </horizontal>
            <vertical>
               <samples>10</samples>
               <resolution>1</resolution> 
               <min_angle>-0.0174533</min_angle>
               <max_angle>0.0174533</max_angle> 
            </vertical>
         </scan>
         <range>
            <min>0.01</min>
            <max>2</max>
            <resolution>0.02</resolution>
         </range>
      </ray>
      <plugin filename="libgazebo_ros_range.so" name="gazebo_ros_range">
         <gaussianNoise>0.005</gaussianNoise>
         <alwaysOn>true</alwaysOn>
         <updateRate>50</updateRate>
         <topicName>sensor/ir_right</topicName>
         <frameName>ir_right_link</frameName>
         <radiation>INFRARED</radiation>
         <fov>0.2967</fov>
      </plugin>
   </sensor>  
   </gazebo>



  <!--  Add ultrasonuc   Left   -->

  <joint name="ir_left_joint" type="fixed">
    <parent link="base_link"/>
    <child link="ir_left_link"/>
    <origin xyz="0.21 0.25 -0.13" rpy="0 0 1.57"/>
  </joint>

  <link name="ir_left_link"/>

  <gazebo reference="ir_left_link">        
   <sensor type="ray" name="ir_left">
      <pose>0 0 0 0 0 0</pose>
      <visualize>false</visualize>
      <update_rate>50</update_rate>
      <ray>
         <scan>
            <horizontal>
               <samples>10</samples>
               <resolution>1</resolution> 
               <min_angle>-0.0349066</min_angle>
               <max_angle>0.0349066</max_angle>
            </horizontal>
            <vertical>
               <samples>10</samples>
               <resolution>1</resolution> 
               <min_angle>-0.0174533</min_angle>
               <max_angle>0.0174533</max_angle> 
            </vertical>
         </scan>
         <range>
            <min>0.01</min>
            <max>2</max>
            <resolution>0.02</resolution>
         </range>
      </ray>
      <plugin filename="libgazebo_ros_range.so" name="gazebo_ros_range">
         <gaussianNoise>0.005</gaussianNoise>
         <alwaysOn>true</alwaysOn>
         <updateRate>50</updateRate>
         <topicName>sensor/ir_left</topicName>
         <frameName>ir_left_link</frameName>
         <radiation>INFRARED</radiation>
         <fov>0.2967</fov>
      </plugin>
   </sensor>  
   </gazebo>


   <!--  Add Cliff front   -->

  <joint name="cliff_front_joint" type="fixed">
    <parent link="base_link"/>
    <child link="cliff_front_link"/>
    <origin xyz="0.38 0.0 -0.075" rpy="0 1.5708 0"/>
  </joint>

  <link name="cliff_front_link"/>

  <gazebo reference="cliff_front_link">        
   <sensor type="ray" name="cliff_front">
      <pose>0 0 0 0 0 0</pose>
      <visualize>true</visualize>
      <update_rate>50</update_rate>
      <ray>
         <scan>
            <horizontal>
               <samples>10</samples>
               <resolution>1</resolution> 
               <min_angle>-0.0349066</min_angle>
               <max_angle>0.0349066</max_angle>
            </horizontal>
            <vertical>
               <samples>10</samples>
               <resolution>1</resolution> 
               <min_angle>-0.0174533</min_angle>
               <max_angle>0.0174533</max_angle> 
            </vertical>
         </scan>
         <range>
            <min>0.01</min>
            <max>2</max>
            <resolution>0.02</resolution>
         </range>
      </ray>
      <plugin filename="libgazebo_ros_range.so" name="gazebo_ros_range">
         <gaussianNoise>0.005</gaussianNoise>
         <alwaysOn>true</alwaysOn>
         <updateRate>50</updateRate>
         <topicName>sensor/cliff_front</topicName>
         <frameName>cliff_front_link</frameName>
         <radiation>INFRARED</radiation>
         <fov>0.2967</fov>
      </plugin>
   </sensor>  
   </gazebo>


   <!--  Add Cliff left   -->

  <joint name="cliff_left_joint" type="fixed">
    <parent link="base_link"/>
    <child link="cliff_left_link"/>
    <origin xyz="0.312 0.26 -0.075" rpy="0 1.5708 0"/>
  </joint>

  <link name="cliff_left_link"/>

  <gazebo reference="cliff_left_link">        
   <sensor type="ray" name="cliff_left">
      <pose>0 0 0 0 0 0</pose>
      <visualize>false</visualize>
      <update_rate>50</update_rate>
      <ray>
         <scan>
            <horizontal>
               <samples>10</samples>
               <resolution>1</resolution> 
               <min_angle>-0.0349066</min_angle>
               <max_angle>0.0349066</max_angle>
            </horizontal>
            <vertical>
               <samples>10</samples>
               <resolution>1</resolution> 
               <min_angle>-0.0174533</min_angle>
               <max_angle>0.0174533</max_angle> 
            </vertical>
         </scan>
         <range>
            <min>0.01</min>
            <max>2</max>
            <resolution>0.02</resolution>
         </range>
      </ray>
      <plugin filename="libgazebo_ros_range.so" name="gazebo_ros_range">
         <gaussianNoise>0.005</gaussianNoise>
         <alwaysOn>true</alwaysOn>
         <updateRate>50</updateRate>
         <topicName>sensor/cliff_left</topicName>
         <frameName>cliff_left_link</frameName>
         <radiation>INFRARED</radiation>
         <fov>0.2967</fov>
      </plugin>
   </sensor>  
   </gazebo>


   <!--  Add Cliff Right   -->

  <joint name="cliff_right_joint" type="fixed">
    <parent link="base_link"/>
    <child link="cliff_right_link"/>
    <origin xyz="0.312 -0.26 -0.075" rpy="0 1.5708 0"/>
  </joint>

  <link name="cliff_right_link"/>

  <gazebo reference="cliff_right_link">        
   <sensor type="ray" name="cliff_right">
      <pose>0 0 0 0 0 0</pose>
      <visualize>false</visualize>
      <update_rate>50</update_rate>
      <ray>
         <scan>
            <horizontal>
               <samples>10</samples>
               <resolution>1</resolution> 
               <min_angle>-0.0349066</min_angle>
               <max_angle>0.0349066</max_angle>
            </horizontal>
            <vertical>
               <samples>10</samples>
               <resolution>1</resolution> 
               <min_angle>-0.0174533</min_angle>
               <max_angle>0.0174533</max_angle> 
            </vertical>
         </scan>
         <range>
            <min>0.01</min>
            <max>2</max>
            <resolution>0.02</resolution>
         </range>
      </ray>
      <plugin filename="libgazebo_ros_range.so" name="gazebo_ros_range">
         <gaussianNoise>0.005</gaussianNoise>
         <alwaysOn>true</alwaysOn>
         <updateRate>50</updateRate>
         <topicName>sensor/cliff_right</topicName>
         <frameName>cliff_right_link</frameName>
         <radiation>INFRARED</radiation>
         <fov>0.2967</fov>
      </plugin>
   </sensor>  
   </gazebo>

</robot>
